<<<<<<< HEAD
<sdf version='1.6'>
  <model name='virat'>
    <link name='base_link'>
      <pose frame=''>0 0 0 0 -0 0</pose>
      <inertial>
        <pose frame=''>0.04 0 0 0 -0 0</pose>
        <mass>6</mass>
        <inertia>
          <ixx>0.15</ixx>
          <ixy>0.15</ixy>
          <ixz>0.15</ixz>
          <iyy>0.2556</iyy>
          <iyz>0.15</iyz>
          <izz>0.2556</izz>
        </inertia>
      </inertial>
      <collision name='base_link_collision'>
        <pose frame=''>0 0 0 0 -0 0</pose>
=======
<?xml version="1.0" ?>
<sdf version="1.5">
  <model name="virat">
    <static>false</static>
    <link name="base_link">
      <collision name="collision">
        <geometry>
          <mesh>
            <uri>model://virat/meshes/bot2.dae</uri>
          </mesh>
        </geometry>
      </collision>
      <visual name="virat_body">
>>>>>>> 3f20f738ae0f54869a4eaa44299b4808d3346e59
        <geometry>
          <mesh>
            <scale>1 1 1</scale>
            <uri>model://virat_gazebo/models/virat/meshes/bot2.dae</uri>
          </mesh>
        </geometry>
      </collision>
      <collision name='base_link_fixed_joint_lump__connect_castor_link_collision_1'>
        <pose frame=''>0 0 0 3.14159 1.57079 3.14159</pose>
        <geometry>
          <cylinder>
            <length>0.48</length>
            <radius>0.006</radius>
          </cylinder>
        </geometry>
      </collision>
      <collision name='base_link_fixed_joint_lump__castor_link_collision_2'>
        <pose frame=''>0.48 0 0 0 -0 0</pose>
        <geometry>
          <mesh>
            <scale>1 1 1</scale>
            <uri>model://virat_gazebo/models/virat/meshes/castors1.dae</uri>
          </mesh>
        </geometry>
      </collision>
      <visual name='base_link_visual'>
        <pose frame=''>0 0 0 0 -0 0</pose>
        <geometry>
          <mesh>
            <scale>1 1 1</scale>
            <uri>model://virat_gazebo/models/virat/meshes/bot2.dae</uri>
          </mesh>
        </geometry>
      </visual>
      <visual name='base_link_fixed_joint_lump__connect_castor_link_visual_1'>
        <pose frame=''>0 0 0 3.14159 1.57079 3.14159</pose>
        <geometry>
          <cylinder>
            <length>0.48</length>
            <radius>0.006</radius>
          </cylinder>
        </geometry>
      </visual>
      <visual name='base_link_fixed_joint_lump__castor_link_visual_2'>
        <pose frame=''>0.48 0 0 0 -0 0</pose>
        <geometry>
          <mesh>
            <scale>1 1 1</scale>
            <uri>model://virat_gazebo/models/virat/meshes/castors1.dae</uri>
          </mesh>
        </geometry>
      </visual>
    </link>
    <link name='left_wheel'>
      <pose frame=''>0 0.323 0 0 -0 0</pose>
      <inertial>
        <pose frame=''>0 0 0 0 -0 0</pose>
        <mass>0.5</mass>
        <inertia>
          <ixx>0.005</ixx>
          <ixy>0.005</ixy>
          <ixz>0.005</ixz>
          <iyy>0.005</iyy>
          <iyz>0.005</iyz>
          <izz>0.005</izz>
        </inertia>
      </inertial>
      <collision name='left_wheel_collision'>
        <pose frame=''>0 0 0 0 -0 0</pose>
        <geometry>
          <mesh>
            <scale>1 1 1</scale>
            <uri>model://virat_gazebo/models/virat/meshes/tyre1.dae</uri>
          </mesh>
        </geometry>
      </collision>
      <visual name='left_wheel_visual'>
        <pose frame=''>0 0 0 0 -0 0</pose>
        <geometry>
          <mesh>
            <scale>1 1 1</scale>
            <uri>model://virat_gazebo/models/virat/meshes/tyre1.dae</uri>
          </mesh>
        </geometry>
      </visual>
    </link>
    <joint name='left_wheel_joint' type='revolute'>
      <child>left_wheel</child>
      <parent>base_link</parent>
      <axis>
        <xyz>0 1 0</xyz>
        <limit>
          <lower>-1e+16</lower>
          <upper>1e+16</upper>
        </limit>
        <dynamics>
          <spring_reference>0</spring_reference>
          <spring_stiffness>0</spring_stiffness>
        </dynamics>
        <use_parent_model_frame>1</use_parent_model_frame>
      </axis>
    </joint>
    <link name='right_wheel'>
      <pose frame=''>0 -0.323 0 0 -0 0</pose>
      <inertial>
        <pose frame=''>0 0 0 0 -0 0</pose>
        <mass>0.5</mass>
        <inertia>
          <ixx>0.05</ixx>
          <ixy>0.05</ixy>
          <ixz>0.05</ixz>
          <iyy>0.05</iyy>
          <iyz>0.05</iyz>
          <izz>0.05</izz>
        </inertia>
      </inertial>
      <collision name='right_wheel_collision'>
        <pose frame=''>0 0 0 0 -0 0</pose>
        <geometry>
          <mesh>
            <scale>1 1 1</scale>
            <uri>model://virat_gazebo/models/virat/meshes/tyre1.dae</uri>
          </mesh>
        </geometry>
      </collision>
      <visual name='right_wheel_visual'>
        <pose frame=''>0 0 0 0 -0 0</pose>
        <geometry>
          <mesh>
            <scale>1 1 1</scale>
            <uri>model://virat_gazebo/models/virat/meshes/tyre1.dae</uri>
          </mesh>
        </geometry>
      </visual>
    </link>
<<<<<<< HEAD
    <joint name='right_wheel_joint' type='revolute'>
=======

    <!-- The LIDAR thing not adding it rn.
    <link name = "front_thing">
        <pose>0.75 0 0.5 0 0 0</pose>
        <collision name="collision">
          <geometry>
            <cylinder>
              <radius>.1</radius>
              <length>1</length>
            </cylinder>
          </geometry>
        </collision>
      <visual name="visual">
        <geometry>
          <mesh>
            <uri>model://virat/meshes/sick-lms1xx.dae</uri>
          </mesh>
        </geometry>
      </visual>
    </link> -->

    <!-- ==================== Wheels =============== -->
    <link name="left_wheel">
      <pose>0 0.34 0 0 0 0</pose>
      <collision name="collision">
        <geometry>
          <mesh>
            <uri>model://virat/meshes/tyre1.dae</uri>
          </mesh>
        </geometry>
      </collision>
      <visual name="visual">
        <geometry>
          <mesh>
            <uri>model://virat/meshes/tyre1.dae</uri>
          </mesh>
        </geometry>
      </visual>
    </link>

    <link name="right_wheel">
      <pose>0 -0.34 0 0 0 0</pose>
      <collision name="collision">
        <geometry>
          <mesh>
            <uri>model://virat/meshes/tyre1.dae</uri>
          </mesh>
        </geometry>
      </collision>
      <visual name="visual">
        <geometry>
          <mesh>
            <uri>model://virat/meshes/tyre1.dae</uri>
          </mesh>
        </geometry>
      </visual>
    </link>

    <!-- Joints for Wheels -->
    <joint type="revolute" name="left_wheel_hinge">
      <pose>0 -0.34 0 0 0 0</pose>
      <child>left_wheel</child>
      <parent>base_link</parent>
      <axis>
        <xyz>0 1 0</xyz>
      </axis>
    </joint>

    <joint type="revolute" name="right_wheel_hinge">
      <pose>0 0.34 0 0 0 0</pose>
>>>>>>> 3f20f738ae0f54869a4eaa44299b4808d3346e59
      <child>right_wheel</child>
      <parent>base_link</parent>
      <axis>
        <xyz>0 1 0</xyz>
<<<<<<< HEAD
        <limit>
          <lower>-1e+16</lower>
          <upper>1e+16</upper>
        </limit>
        <dynamics>
          <spring_reference>0</spring_reference>
          <spring_stiffness>0</spring_stiffness>
        </dynamics>
        <use_parent_model_frame>1</use_parent_model_frame>
=======
>>>>>>> 3f20f738ae0f54869a4eaa44299b4808d3346e59
      </axis>
    </joint>
  </model>
</sdf>